package task

import (
	"errors"
	"fmt"
)

// ErrTaskfileAlreadyExists is returned on creating a Taskfile if one already exists
var ErrTaskfileAlreadyExists = errors.New("task: A Taskfile already exists")

type taskNotFoundError struct {
	taskName string
}

func (err *taskNotFoundError) Error() string {
	return fmt.Sprintf(`task: Task "%s" not found`, err.taskName)
}

type taskRunError struct {
	taskName string
	err      error
}

func (err *taskRunError) Error() string {
	return fmt.Sprintf(`task: Failed to run task "%s": %v`, err.taskName, err.err)
}

// MaximumTaskCallExceededError is returned when a task is called too
// many times. In this case you probably have a cyclic dependendy or
// infinite loop
type MaximumTaskCallExceededError struct {
	task string
}

func (e *MaximumTaskCallExceededError) Error() string {
	return fmt.Sprintf(
		`task: maximum task call exceeded (%d) for task "%s": probably an cyclic dep or infinite loop`,
		MaximumTaskCall,
		e.task,
	)
}
